I'm sorry, but an uncaught exception occurred.

While running game code:
  File "renpy/common/00start.rpy", line 185, in script
    python:
  File "renpy/common/00start.rpy", line 186, in <module>
    renpy.execute_default_statement(True)
Exception: store.day_num is being given a default a second time.

-- Full Traceback ------------------------------------------------------------

Full traceback:
  File "C:\Users\Benjamin Shu\Documents\renpy-6.99.14.1-sdk\renpy\bootstrap.py", line 313, in bootstrap
    renpy.main.main()
  File "C:\Users\Benjamin Shu\Documents\renpy-6.99.14.1-sdk\renpy\main.py", line 513, in main
    run(restart)
  File "C:\Users\Benjamin Shu\Documents\renpy-6.99.14.1-sdk\renpy\main.py", line 139, in run
    renpy.execution.run_context(True)
  File "C:\Users\Benjamin Shu\Documents\renpy-6.99.14.1-sdk\renpy\execution.py", line 876, in run_context
    context.run()
  File "renpy/common/00start.rpy", line 185, in script
    python:
  File "C:\Users\Benjamin Shu\Documents\renpy-6.99.14.1-sdk\renpy\ast.py", line 881, in execute
    renpy.python.py_exec_bytecode(self.code.bytecode, self.hide, store=self.store)
  File "C:\Users\Benjamin Shu\Documents\renpy-6.99.14.1-sdk\renpy\python.py", line 1913, in py_exec_bytecode
    exec bytecode in globals, locals
  File "renpy/common/00start.rpy", line 186, in <module>
    renpy.execute_default_statement(True)
  File "C:\Users\Benjamin Shu\Documents\renpy-6.99.14.1-sdk\renpy\exports.py", line 3334, in execute_default_statement
    i.set_default(start)
  File "game/script_02_Assets.rpyc", line 35, in set_default
    �uR� �$Q��\�RC2�VA/��Ȋ	0�;u%-@e6Ui	*�Pe���:^�Y*�|�JQ%���5TFJ�$��O2��4\�
Exception: store.day_num is being given a default a second time.

Windows-8-6.2.9200
Ren'Py 7.1.3.1092
SBU Senior Project 1.0
Thu Apr 18 16:06:12 2019
